Workbook

Sheet ReadMe
A1: Top 10 Global Banks — Financial Health Dashboard (2021–2025)
A3: RESEARCH QUESTION
A4: How does the overall financial health (profitability, efficiency, capital strength, and momentum) of the
A5: largest European banks compare with the largest American banks, and how has this evolved 2021-2025?
A7: SHEETS IN THIS WORKBOOK
A8: Banks - dimension table: bank name, country, region, HQ coordinates (for the Power BI map)
A9: FX_Rates - approximate annual average EUR->USD and GBP->USD rates, used for currency normalization
A10: Financials_Raw - raw reported figures per bank/year, in NATIVE currency (as published by each bank)
A11: Financials_USD - same data converted to USD using live Excel formulas (VLOOKUP/IF) - inspect column G & H
A12: Processed_for_PowerBI - final clean table (USD, +YoY growth, +Financial Health Score) produced by the Java program
A14: DATA SOURCES
A15: Figures compiled from each bank's FY2021-FY2025 annual reports, 10-K / 20-F filings, and Q4/full-year earnings
... A27: See README.md in the project root for the full step-by-step guide.

Sheet Banks
A1: BankID | B1: BankName | C1: Ticker | D1: Country | E1: Region | F1: HQCity | G1: Latitude | H1: Longitude | I1: ReportingCurrency
A2: 1 | B2: JPMorgan Chase | C2: JPM | D2: United States | E2: Americas | F2: New York | G2: 40.7128 | H2: -74.006 | I2: USD
A3: 2 | B3: Bank of America | C3: BAC | D3: United States | E3: Americas | F3: Charlotte | G3: 35.2271 | H3: -80.8431 | I3: USD
A4: 3 | B4: Citigroup | C4: C | D4: United States | E4: Americas | F4: New York | G4: 40.7128 | H4: -74.006 | I4: USD
A5: 4 | B5: Wells Fargo | C5: WFC | D5: United States | E5: Americas | F5: San Francisco | G5: 37.7749 | H5: -122.4194 | I5: USD
A6: 5 | B6: Goldman Sachs | C6: GS | D6: United States | E6: Americas | F6: New York | G6: 40.7128 | H6: -74.006 | I6: USD
A7: 6 | B7: BNP Paribas | C7: BNP | D7: France | E7: Europe | F7: Paris | G7: 48.8566 | H7: 2.3522 | I7: EUR
A8: 7 | B8: Banco Santander | C8: SAN | D8: Spain | E8: Europe | F8: Madrid | G8: 40.4168 | H8: -3.7038 | I8: EUR
A9: 8 | B9: Deutsche Bank | C9: DBK | D9: Germany | E9: Europe | F9: Frankfurt | G9: 50.1109 | H9: 8.6821 | I9: EUR
A10: 9 | B10: Barclays | C10: BARC | D10: United Kingdom | E10: Europe | F10: London | G10: 51.5074 | H10: -0.1278 | I10: GBP
A11: 10 | B11: UBS Group | C11: UBSG | D11: Switzerland | E11: Europe | F11: Zurich | G11: 47.3769 | H11: 8.5417 | I11: USD
A12: 11 | B12: Societe Generale | C12: GLE | D12: France | E12: Europe | F12: Paris | G12: 48.8566 | H12: 2.3522 | I12: EUR

Sheet FX_Rates
A1: Year | B1: EUR_to_USD | C1: GBP_to_USD | D1: Source: approximate annual average market rates (ECB / Federal Reserve historical series). Verify exact figures if precision is required for grading.
A2: 2021 | B2: 1.183 | C2: 1.376
A3: 2022 | B3: 1.053 | C3: 1.237
A4: 2023 | B4: 1.082 | C4: 1.244
A5: 2024 | B5: 1.082 | C5: 1.278
A6: 2025 | B6: 1.08 | C6: 1.28

Sheet Financials_Raw
A1: BankID | B1: Year | C1: Currency | D1: Revenue_M | E1: NetIncome_M | F1: TotalAssets_M | G1: ROE_Pct | H1: CET1_Pct | I1: Employees | J1: Source: company annual reports / earnings releases (10-K, 20-F, FY results press releases), 2021-2025. Figures in millions of native currency.
A2: 1 | B2: 2021 | C2: USD | D2: 121640 | E2: 48334 | F2: 3743567 | G2: 23 | H2: 13.1 | I2: 271025
A3: 1 | B3: 2022 | C3: USD | D3: 128695 | E3: 37676 | F3: 3665743 | G3: 18 | H3: 12.5 | I3: 293723
A4: 1 | B4: 2023 | C4: USD | D4: 158104 | E4: 49552 | F4: 3875393 | G4: 19 | H4: 15 | I4: 309926
A5: 1 | B5: 2024 | C5: USD | D5: 177556 | E5: 58471 | F5: 4002814 | G5: 21 | H5: 15.3 | I5: 316043
A6: 1 | B6: 2025 | C6: USD | D6: 185600 | E6: 57048 | F6: 4400000 | G6: 17 | H6: 14.5 | I6: 317230
A7: 2 | B7: 2021 | C7: USD | D7: 89113 | E7: 31978 | F7: 3169495 | G7: 11 | H7: 10.6 | I7: 213000
A8: 2 | B8: 2022 | C8: USD | D8: 94951 | E8: 27528 | F8: 3051375 | G8: 10 | H8: 11.2 | I8: 217000
A9: 2 | B9: 2023 | C9: USD | D9: 98571 | E9: 26515 | F9: 3180151 | G9: 8.8 | H9: 11.8 | I9: 213000
A10: 2 | B10: 2024 | C10: USD | D10: 105648 | E10: 27000 | F10: 3298880 | G10: 9.3 | H10: 11.9 | I10: 213000
A11: 2 | B11: 2025 | C11: USD | D11: 113100 | E11: 30500 | F11: 3380000 | G11: 10.2 | H11: 11.7 | I11: 215000
A12: 3 | B12: 2021 | C12: USD | D12: 71884 | E12: 21952 | F12: 2291413 | G12: 9.5 | H12: 12.2 | I12: 223400
A13: 3 | B13: 2022 | C13: USD | D13: 75338 | E13: 14845 | F13: 2416676 | G13: 6 | H13: 13 | I13: 240000
... A56: 11 | B56: 2025 | C56: EUR | D56: 27254 | E56: 6000 | F56: 1500000 | G56: 10.2 | H56: 13.5 | I56: 82000

Sheet Financials_USD
A1: BankID | B1: BankName | C1: Year | D1: Currency | E1: Revenue_Native_M | F1: NetIncome_Native_M | G1: FX_Rate_to_USD | H1: Revenue_USD_M | I1: NetIncome_USD_M | J1: NetMargin_Pct | K1: ROE_Pct | L1: CET1_Pct | N1: This sheet recreates the USD conversion using live Excel formulas (VLOOKUP into Banks / FX_Rates) so you can see the calculation step-by-step. The Java program performs the same conversion programmatically, plus extra metrics (YoY growth, Financial Health Score) — see the Processed_for_PowerBI sheet.
A2: =Financials_Raw!A2 -> 1 | B2: =VLOOKUP(A2,Banks!$A:$B,2,FALSE()) -> JPMorgan Chase | C2: =Financials_Raw!B2 -> 2021 | D2: =Financials_Raw!C2 -> USD | E2: =Financials_Raw!D2 -> 121640 | F2: =Financials_Raw!E2 -> 48334 | G2: =IF(D2="USD",1,IF(D2="EUR",VLOOKUP(C2,FX_Rates!$A:$C,2,FALSE()),VLOOKUP(C2,FX_Rates!$A:$C,3,FALSE()))) -> 1 | H2: =E2*G2 -> 121640 | I2: =F2*G2 -> 48334 | J2: =IF(H2=0,0,I2/H2*100) -> 39.735284 | K2: =Financials_Raw!G2 -> 23 | L2: =Financials_Raw!H2 -> 13.1
A3: =Financials_Raw!A3 -> 1 | B3: =VLOOKUP(A3,Banks!$A:$B,2,FALSE()) -> JPMorgan Chase | C3: =Financials_Raw!B3 -> 2022 | D3: =Financials_Raw!C3 -> USD | E3: =Financials_Raw!D3 -> 128695 | F3: =Financials_Raw!E3 -> 37676 | G3: =IF(D3="USD",1,IF(D3="EUR",VLOOKUP(C3,FX_Rates!$A:$C,2,FALSE()),VLOOKUP(C3,FX_Rates!$A:$C,3,FALSE()))) -> 1 | H3: =E3*G3 -> 128695 | I3: =F3*G3 -> 37676 | J3: =IF(H3=0,0,I3/H3*100) -> 29.275419 | K3: =Financials_Raw!G3 -> 18 | L3: =Financials_Raw!H3 -> 12.5
A4: =Financials_Raw!A4 -> 1 | B4: =VLOOKUP(A4,Banks!$A:$B,2,FALSE()) -> JPMorgan Chase | C4: =Financials_Raw!B4 -> 2023 | D4: =Financials_Raw!C4 -> USD | E4: =Financials_Raw!D4 -> 158104 | F4: =Financials_Raw!E4 -> 49552 | G4: =IF(D4="USD",1,IF(D4="EUR",VLOOKUP(C4,FX_Rates!$A:$C,2,FALSE()),VLOOKUP(C4,FX_Rates!$A:$C,3,FALSE()))) -> 1 | H4: =E4*G4 -> 158104 | I4: =F4*G4 -> 49552 | J4: =IF(H4=0,0,I4/H4*100) -> 31.341396 | K4: =Financials_Raw!G4 -> 19 | L4: =Financials_Raw!H4 -> 15
A5: =Financials_Raw!A5 -> 1 | B5: =VLOOKUP(A5,Banks!$A:$B,2,FALSE()) -> JPMorgan Chase | C5: =Financials_Raw!B5 -> 2024 | D5: =Financials_Raw!C5 -> USD | E5: =Financials_Raw!D5 -> 177556 | F5: =Financials_Raw!E5 -> 58471 | G5: =IF(D5="USD",1,IF(D5="EUR",VLOOKUP(C5,FX_Rates!$A:$C,2,FALSE()),VLOOKUP(C5,FX_Rates!$A:$C,3,FALSE()))) -> 1 | H5: =E5*G5 -> 177556 | I5: =F5*G5 -> 58471 | J5: =IF(H5=0,0,I5/H5*100) -> 32.931019 | K5: =Financials_Raw!G5 -> 21 | L5: =Financials_Raw!H5 -> 15.3
A6: =Financials_Raw!A6 -> 1 | B6: =VLOOKUP(A6,Banks!$A:$B,2,FALSE()) -> JPMorgan Chase | C6: =Financials_Raw!B6 -> 2025 | D6: =Financials_Raw!C6 -> USD | E6: =Financials_Raw!D6 -> 185600 | F6: =Financials_Raw!E6 -> 57048 | G6: =IF(D6="USD",1,IF(D6="EUR",VLOOKUP(C6,FX_Rates!$A:$C,2,FALSE()),VLOOKUP(C6,FX_Rates!$A:$C,3,FALSE()))) -> 1 | H6: =E6*G6 -> 185600 | I6: =F6*G6 -> 57048 | J6: =IF(H6=0,0,I6/H6*100) -> 30.737069 | K6: =Financials_Raw!G6 -> 17 | L6: =Financials_Raw!H6 -> 14.5
A7: =Financials_Raw!A7 -> 2 | B7: =VLOOKUP(A7,Banks!$A:$B,2,FALSE()) -> Bank of America | C7: =Financials_Raw!B7 -> 2021 | D7: =Financials_Raw!C7 -> USD | E7: =Financials_Raw!D7 -> 89113 | F7: =Financials_Raw!E7 -> 31978 | G7: =IF(D7="USD",1,IF(D7="EUR",VLOOKUP(C7,FX_Rates!$A:$C,2,FALSE()),VLOOKUP(C7,FX_Rates!$A:$C,3,FALSE()))) -> 1 | H7: =E7*G7 -> 89113 | I7: =F7*G7 -> 31978 | J7: =IF(H7=0,0,I7/H7*100) -> 35.884776 | K7: =Financials_Raw!G7 -> 11 | L7: =Financials_Raw!H7 -> 10.6
A8: =Financials_Raw!A8 -> 2 | B8: =VLOOKUP(A8,Banks!$A:$B,2,FALSE()) -> Bank of America | C8: =Financials_Raw!B8 -> 2022 | D8: =Financials_Raw!C8 -> USD | E8: =Financials_Raw!D8 -> 94951 | F8: =Financials_Raw!E8 -> 27528 | G8: =IF(D8="USD",1,IF(D8="EUR",VLOOKUP(C8,FX_Rates!$A:$C,2,FALSE()),VLOOKUP(C8,FX_Rates!$A:$C,3,FALSE()))) -> 1 | H8: =E8*G8 -> 94951 | I8: =F8*G8 -> 27528 | J8: =IF(H8=0,0,I8/H8*100) -> 28.991796 | K8: =Financials_Raw!G8 -> 10 | L8: =Financials_Raw!H8 -> 11.2
A9: =Financials_Raw!A9 -> 2 | B9: =VLOOKUP(A9,Banks!$A:$B,2,FALSE()) -> Bank of America | C9: =Financials_Raw!B9 -> 2023 | D9: =Financials_Raw!C9 -> USD | E9: =Financials_Raw!D9 -> 98571 | F9: =Financials_Raw!E9 -> 26515 | G9: =IF(D9="USD",1,IF(D9="EUR",VLOOKUP(C9,FX_Rates!$A:$C,2,FALSE()),VLOOKUP(C9,FX_Rates!$A:$C,3,FALSE()))) -> 1 | H9: =E9*G9 -> 98571 | I9: =F9*G9 -> 26515 | J9: =IF(H9=0,0,I9/H9*100) -> 26.899392 | K9: =Financials_Raw!G9 -> 8.8 | L9: =Financials_Raw!H9 -> 11.8
A10: =Financials_Raw!A10 -> 2 | B10: =VLOOKUP(A10,Banks!$A:$B,2,FALSE()) -> Bank of America | C10: =Financials_Raw!B10 -> 2024 | D10: =Financials_Raw!C10 -> USD | E10: =Financials_Raw!D10 -> 105648 | F10: =Financials_Raw!E10 -> 27000 | G10: =IF(D10="USD",1,IF(D10="EUR",VLOOKUP(C10,FX_Rates!$A:$C,2,FALSE()),VLOOKUP(C10,FX_Rates!$A:$C,3,FALSE()))) -> 1 | H10: =E10*G10 -> 105648 | I10: =F10*G10 -> 27000 | J10: =IF(H10=0,0,I10/H10*100) -> 25.556565 | K10: =Financials_Raw!G10 -> 9.3 | L10: =Financials_Raw!H10 -> 11.9
A11: =Financials_Raw!A11 -> 2 | B11: =VLOOKUP(A11,Banks!$A:$B,2,FALSE()) -> Bank of America | C11: =Financials_Raw!B11 -> 2025 | D11: =Financials_Raw!C11 -> USD | E11: =Financials_Raw!D11 -> 113100 | F11: =Financials_Raw!E11 -> 30500 | G11: =IF(D11="USD",1,IF(D11="EUR",VLOOKUP(C11,FX_Rates!$A:$C,2,FALSE()),VLOOKUP(C11,FX_Rates!$A:$C,3,FALSE()))) -> 1 | H11: =E11*G11 -> 113100 | I11: =F11*G11 -> 30500 | J11: =IF(H11=0,0,I11/H11*100) -> 26.967286 | K11: =Financials_Raw!G11 -> 10.2 | L11: =Financials_Raw!H11 -> 11.7
A12: =Financials_Raw!A12 -> 3 | B12: =VLOOKUP(A12,Banks!$A:$B,2,FALSE()) -> Citigroup | C12: =Financials_Raw!B12 -> 2021 | D12: =Financials_Raw!C12 -> USD | E12: =Financials_Raw!D12 -> 71884 | F12: =Financials_Raw!E12 -> 21952 | G12: =IF(D12="USD",1,IF(D12="EUR",VLOOKUP(C12,FX_Rates!$A:$C,2,FALSE()),VLOOKUP(C12,FX_Rates!$A:$C,3,FALSE()))) -> 1 | H12: =E12*G12 -> 71884 | I12: =F12*G12 -> 21952 | J12: =IF(H12=0,0,I12/H12*100) -> 30.538089 | K12: =Financials_Raw!G12 -> 9.5 | L12: =Financials_Raw!H12 -> 12.2
A13: =Financials_Raw!A13 -> 3 | B13: =VLOOKUP(A13,Banks!$A:$B,2,FALSE()) -> Citigroup | C13: =Financials_Raw!B13 -> 2022 | D13: =Financials_Raw!C13 -> USD | E13: =Financials_Raw!D13 -> 75338 | F13: =Financials_Raw!E13 -> 14845 | G13: =IF(D13="USD",1,IF(D13="EUR",VLOOKUP(C13,FX_Rates!$A:$C,2,FALSE()),VLOOKUP(C13,FX_Rates!$A:$C,3,FALSE()))) -> 1 | H13: =E13*G13 -> 75338 | I13: =F13*G13 -> 14845 | J13: =IF(H13=0,0,I13/H13*100) -> 19.704532 | K13: =Financials_Raw!G13 -> 6 | L13: =Financials_Raw!H13 -> 13
... A56: =Financials_Raw!A56 -> 11 | B56: =VLOOKUP(A56,Banks!$A:$B,2,FALSE()) -> Societe Generale | C56: =Financials_Raw!B56 -> 2025 | D56: =Financials_Raw!C56 -> EUR | E56: =Financials_Raw!D56 -> 27254 | F56: =Financials_Raw!E56 -> 6000 | G56: =IF(D56="USD",1,IF(D56="EUR",VLOOKUP(C56,FX_Rates!$A:$C,2,FALSE()),VLOOKUP(C56,FX_Rates!$A:$C,3,FALSE()))) -> 1.08 | H56: =E56*G56 -> 29434.32 | I56: =F56*G56 -> 6480 | J56: =IF(H56=0,0,I56/H56*100) -> 22.015117 | K56: =Financials_Raw!G56 -> 10.2 | L56: =Financials_Raw!H56 -> 13.5

Sheet Processed_for_PowerBI
A1: BankID | B1: BankName | C1: Ticker | D1: Country | E1: Region | F1: HQCity | G1: Latitude | H1: Longitude | I1: Year | J1: Revenue_USD_M | K1: NetIncome_USD_M | L1: TotalAssets_USD_M | M1: ROE_Pct | N1: CET1_Pct | O1: Employees | P1: NetMargin_Pct | Q1: RevenueGrowth_YoY_Pct | R1: NetIncomeGrowth_YoY_Pct | S1: FinancialHealthScore | U1: This is the final, analysis-ready table generated by BankFinancialAnalyzer.java. Import THIS sheet (or the equivalent processed_bank_data.csv) into Power BI.
A2: 1 | B2: JPMorgan Chase | C2: JPM | D2: United States | E2: Americas | F2: New York | G2: 40.7128 | H2: -74.006 | I2: 2021 | J2: 121640 | K2: 48334 | L2: 3743567 | M2: 23 | N2: 13.1 | O2: 271025 | P2: 39.74 | S2: 78.89
A3: 1 | B3: JPMorgan Chase | C3: JPM | D3: United States | E3: Americas | F3: New York | G3: 40.7128 | H3: -74.006 | I3: 2022 | J3: 128695 | K3: 37676 | L3: 3665743 | M3: 18 | N3: 12.5 | O3: 293723 | P3: 29.28 | Q3: 5.8 | R3: -22.05 | S3: 73.22
A4: 1 | B4: JPMorgan Chase | C4: JPM | D4: United States | E4: Americas | F4: New York | G4: 40.7128 | H4: -74.006 | I4: 2023 | J4: 158104 | K4: 49552 | L4: 3875393 | M4: 19 | N4: 15 | O4: 309926 | P4: 31.34 | Q4: 22.85 | R4: 31.52 | S4: 71.94
A5: 1 | B5: JPMorgan Chase | C5: JPM | D5: United States | E5: Americas | F5: New York | G5: 40.7128 | H5: -74.006 | I5: 2024 | J5: 177556 | K5: 58471 | L5: 4002814 | M5: 21 | N5: 15.3 | O5: 316043 | P5: 32.93 | Q5: 12.3 | R5: 18 | S5: 93.3
A6: 1 | B6: JPMorgan Chase | C6: JPM | D6: United States | E6: Americas | F6: New York | G6: 40.7128 | H6: -74.006 | I6: 2025 | J6: 185600 | K6: 57048 | L6: 4400000 | M6: 17 | N6: 14.5 | O6: 317230 | P6: 30.74 | Q6: 4.53 | R6: -2.43 | S6: 76.62
A7: 2 | B7: Bank of America | C7: BAC | D7: United States | E7: Americas | F7: Charlotte | G7: 35.2271 | H7: -80.8431 | I7: 2021 | J7: 89113 | K7: 31978 | L7: 3169495 | M7: 11 | N7: 10.6 | O7: 213000 | P7: 35.88 | S7: 40.54
A8: 2 | B8: Bank of America | C8: BAC | D8: United States | E8: Americas | F8: Charlotte | G8: 35.2271 | H8: -80.8431 | I8: 2022 | J8: 94951 | K8: 27528 | L8: 3051375 | M8: 10 | N8: 11.2 | O8: 217000 | P8: 28.99 | Q8: 6.55 | R8: -13.92 | S8: 45.81
A9: 2 | B9: Bank of America | C9: BAC | D9: United States | E9: Americas | F9: Charlotte | G9: 35.2271 | H9: -80.8431 | I9: 2023 | J9: 98571 | K9: 26515 | L9: 3180151 | M9: 8.8 | N9: 11.8 | O9: 213000 | P9: 26.9 | Q9: 3.81 | R9: -3.68 | S9: 22.45
A10: 2 | B10: Bank of America | C10: BAC | D10: United States | E10: Americas | F10: Charlotte | G10: 35.2271 | H10: -80.8431 | I10: 2024 | J10: 105648 | K10: 27000 | L10: 3298880 | M10: 9.3 | N10: 11.9 | O10: 213000 | P10: 25.56 | Q10: 7.18 | R10: 1.83 | S10: 39.67
A11: 2 | B11: Bank of America | C11: BAC | D11: United States | E11: Americas | F11: Charlotte | G11: 35.2271 | H11: -80.8431 | I11: 2025 | J11: 113100 | K11: 30500 | L11: 3380000 | M11: 10.2 | N11: 11.7 | O11: 215000 | P11: 26.97 | Q11: 7.05 | R11: 12.96 | S11: 31.8
A12: 3 | B12: Citigroup | C12: C | D12: United States | E12: Americas | F12: New York | G12: 40.7128 | H12: -74.006 | I12: 2021 | J12: 71884 | K12: 21952 | L12: 2291413 | M12: 9.5 | N12: 12.2 | O12: 223400 | P12: 30.54 | S12: 43.12
A13: 3 | B13: Citigroup | C13: C | D13: United States | E13: Americas | F13: New York | G13: 40.7128 | H13: -74.006 | I13: 2022 | J13: 75338 | K13: 14845 | L13: 2416676 | M13: 6 | N13: 13 | O13: 240000 | P13: 19.7 | Q13: 4.8 | R13: -32.38 | S13: 39.39
A14: 3 | B14: Citigroup | C14: C | D14: United States | E14: Americas | F14: New York | G14: 40.7128 | H14: -74.006 | I14: 2023 | J14: 78462 | K14: 9227 | L14: 2411800 | M14: 4 | N14: 13.4 | O14: 239000 | P14: 11.76 | Q14: 4.15 | R14: -37.84 | S14: 15
A15: 3 | B15: Citigroup | C15: C | D15: United States | E15: Americas | F15: New York | G15: 40.7128 | H15: -74.006 | I15: 2024 | J15: 80707 | K15: 12700 | L15: 2352700 | M15: 6.1 | N15: 13.6 | O15: 229000 | P15: 15.74 | Q15: 2.86 | R15: 37.64 | S15: 39.5
A16: 3 | B16: Citigroup | C16: C | D16: United States | E16: Americas | F16: New York | G16: 40.7128 | H16: -74.006 | I16: 2025 | J16: 85200 | K16: 14300 | L16: 2480000 | M16: 6.8 | N16: 13.5 | O16: 223000 | P16: 16.78 | Q16: 5.57 | R16: 12.6 | S16: 18.98
A17: 4 | B17: Wells Fargo | C17: WFC | D17: United States | E17: Americas | F17: San Francisco | G17: 37.7749 | H17: -122.4194 | I17: 2021 | J17: 78492 | K17: 21548 | L17: 1948068 | M17: 10.5 | N17: 11 | O17: 238696 | P17: 27.45 | S17: 36.21
A18: 4 | B18: Wells Fargo | C18: WFC | D18: United States | E18: Americas | F18: San Francisco | G18: 37.7749 | H18: -122.4194 | I18: 2022 | J18: 73785 | K18: 13166 | L18: 1881017 | M18: 6.4 | N18: 10.8 | O18: 238472 | P18: 17.84 | Q18: -6 | R18: -38.9 | S18: 21.73
A19: 4 | B19: Wells Fargo | C19: WFC | D19: United States | E19: Americas | F19: San Francisco | G19: 37.7749 | H19: -122.4194 | I19: 2023 | J19: 82594 | K19: 19142 | L19: 1932469 | M19: 10 | N19: 11.4 | O19: 226400 | P19: 23.18 | Q19: 11.94 | R19: 45.39 | S19: 24.2
A20: 4 | B20: Wells Fargo | C20: WFC | D20: United States | E20: Americas | F20: San Francisco | G20: 37.7749 | H20: -122.4194 | I20: 2024 | J20: 82300 | K20: 19696 | L20: 1929753 | M20: 11.6 | N20: 11.1 | O20: 215637 | P20: 23.93 | Q20: -0.36 | R20: 2.89 | S20: 38.64
A21: 4 | B21: Wells Fargo | C21: WFC | D21: United States | E21: Americas | F21: San Francisco | G21: 37.7749 | H21: -122.4194 | I21: 2025 | J21: 83700 | K21: 21300 | L21: 1950000 | M21: 12.3 | N21: 11.3 | O21: 210000 | P21: 25.45 | Q21: 1.7 | R21: 8.14 | S21: 33.59
A22: 5 | B22: Goldman Sachs | C22: GS | D22: United States | E22: Americas | F22: New York | G22: 40.7128 | H22: -74.006 | I22: 2021 | J22: 59339 | K22: 21635 | L22: 1463988 | M22: 23 | N22: 13.1 | O22: 43900 | P22: 36.46 | S22: 76.69
A23: 5 | B23: Goldman Sachs | C23: GS | D23: United States | E23: Americas | F23: New York | G23: 40.7128 | H23: -74.006 | I23: 2022 | J23: 47365 | K23: 11261 | L23: 1441829 | M23: 10.2 | N23: 14 | O23: 49100 | P23: 23.77 | Q23: -20.18 | R23: -47.95 | S23: 58.28
A24: 5 | B24: Goldman Sachs | C24: GS | D24: United States | E24: Americas | F24: New York | G24: 40.7128 | H24: -74.006 | I24: 2023 | J24: 46254 | K24: 8516 | L24: 1641949 | M24: 7.5 | N24: 14.6 | O24: 45300 | P24: 18.41 | Q24: -2.35 | R24: -24.38 | S24: 34.59
A25: 5 | B25: Goldman Sachs | C25: GS | D25: United States | E25: Americas | F25: New York | G25: 40.7128 | H25: -74.006 | I25: 2024 | J25: 53510 | K25: 14281 | L25: 1761661 | M25: 12.7 | N25: 15 | O25: 46500 | P25: 26.69 | Q25: 15.69 | R25: 67.7 | S25: 75.08
A26: 5 | B26: Goldman Sachs | C26: GS | D26: United States | E26: Americas | F26: New York | G26: 40.7128 | H26: -74.006 | I26: 2025 | J26: 58280 | K26: 17180 | L26: 1850000 | M26: 15 | N26: 15 | O26: 47500 | P26: 29.48 | Q26: 8.91 | R26: 20.3 | S26: 74.95
A27: 6 | B27: BNP Paribas | C27: BNP | D27: France | E27: Europe | F27: Paris | G27: 48.8566 | H27: 2.3522 | I27: 2021 | J27: 52442.39 | K27: 11224.3 | L27: 3115285 | M27: 8.3 | N27: 12.9 | O27: 190000 | P27: 21.4 | S27: 38.7
A28: 6 | B28: BNP Paribas | C28: BNP | D28: France | E28: Europe | F28: Paris | G28: 48.8566 | H28: 2.3522 | I28: 2022 | J28: 48631.75 | K28: 10736.39 | L28: 2807574.9 | M28: 9.8 | N28: 12.3 | O28: 190000 | P28: 22.08 | Q28: -7.27 | R28: -4.35 | S28: 48.42
A29: 6 | B29: BNP Paribas | C29: BNP | D29: France | E29: Europe | F29: Paris | G29: 48.8566 | H29: 2.3522 | I29: 2023 | J29: 49224.51 | K29: 12006.95 | L29: 2804099.3 | M29: 9.5 | N29: 13.2 | O29: 183000 | P29: 24.39 | Q29: 1.22 | R29: 11.83 | S29: 33.87
A30: 6 | B30: BNP Paribas | C30: BNP | D30: France | E30: Europe | F30: Paris | G30: 48.8566 | H30: 2.3522 | I30: 2024 | J30: 52828.65 | K30: 12646.42 | L30: 2806659.3 | M30: 11.5 | N30: 12.7 | O30: 178000 | P30: 23.94 | Q30: 7.32 | R30: 5.33 | S30: 48.27
A31: 6 | B31: BNP Paribas | C31: BNP | D31: France | E31: Europe | F31: Paris | G31: 48.8566 | H31: 2.3522 | I31: 2025 | J31: 55320.84 | K31: 13203 | L31: 2916000 | M31: 11.6 | N31: 12.6 | O31: 178000 | P31: 23.87 | Q31: 4.72 | R31: 4.4 | S31: 37.35
A32: 7 | B32: Banco Santander | C32: SAN | D32: Spain | E32: Europe | F32: Madrid | G32: 40.4168 | H32: -3.7038 | I32: 2021 | J32: 54382.51 | K32: 9610.69 | L32: 1905781.1 | M32: 11.1 | N32: 11.9 | O32: 191589 | P32: 17.67 | S32: 35.75
A33: 7 | B33: Banco Santander | C33: SAN | D33: Spain | E33: Europe | F33: Madrid | G33: 40.4168 | H33: -3.7038 | I33: 2022 | J33: 54978.18 | K33: 10114.06 | L33: 1826595.9 | M33: 13.4 | N33: 12 | O33: 212764 | P33: 18.4 | Q33: 1.1 | R33: 5.24 | S33: 52.41
A34: 7 | B34: Banco Santander | C34: SAN | D34: Spain | E34: Europe | F34: Madrid | G34: 40.4168 | H34: -3.7038 | I34: 2023 | J34: 62118.7 | K34: 11984.23 | L34: 1944386.5 | M34: 14.6 | N34: 12.3 | O34: 212935 | P34: 19.29 | Q34: 12.99 | R34: 18.49 | S34: 37.97
A35: 7 | B35: Banco Santander | C35: SAN | D35: Spain | E35: Europe | F35: Madrid | G35: 40.4168 | H35: -3.7038 | I35: 2024 | J35: 63167.16 | K35: 13605.07 | L35: 1988957.3 | M35: 15.5 | N35: 12.8 | O35: 217864 | P35: 21.54 | Q35: 1.69 | R35: 13.52 | S35: 56.55
A36: 7 | B36: Banco Santander | C36: SAN | D36: Spain | E36: Europe | F36: Madrid | G36: 40.4168 | H36: -3.7038 | I36: 2025 | J36: 67392 | K36: 15229.08 | L36: 2052000 | M36: 16.3 | N36: 13.5 | O36: 220000 | P36: 22.6 | Q36: 6.69 | R36: 11.94 | S36: 59.05
A37: 8 | B37: Deutsche Bank | C37: DBK | D37: Germany | E37: Europe | F37: Frankfurt | G37: 50.1109 | H37: 8.6821 | I37: 2021 | J37: 30028.09 | K37: 2969.33 | L37: 1566128.8 | M37: 3.8 | N37: 13.2 | O37: 84964 | P37: 9.89 | S37: 24.44
A38: 8 | B38: Deutsche Bank | C38: DBK | D38: Germany | E38: Europe | F38: Frankfurt | G38: 50.1109 | H38: 8.6821 | I38: 2022 | J38: 28666.87 | K38: 5958.93 | L38: 1407656.7 | M38: 7.9 | N38: 13.4 | O38: 84955 | P38: 20.79 | Q38: -4.53 | R38: 100.68 | S38: 63.18
A39: 8 | B39: Deutsche Bank | C39: DBK | D39: Germany | E39: Europe | F39: Frankfurt | G39: 50.1109 | H39: 8.6821 | I39: 2023 | J39: 31248.16 | K39: 5295.31 | L39: 1412467.7 | M39: 7.4 | N39: 13.7 | O39: 90130 | P39: 16.95 | Q39: 9 | R39: -11.14 | S39: 28.42
A40: 8 | B40: Deutsche Bank | C40: DBK | D40: Germany | E40: Europe | F40: Frankfurt | G40: 50.1109 | H40: 8.6821 | I40: 2024 | J40: 32568.2 | K40: 2884.61 | L40: 1463772.9 | M40: 4.7 | N40: 13.8 | O40: 90261 | P40: 8.86 | Q40: 4.22 | R40: -45.53 | S40: 20.96
...
